[2024-03-12 06:45:22,201] 1026 httpx - INFO - HTTP Request: POST https://api.openai.com/v1/chat/completions "HTTP/1.1 200 OK"
[2024-03-12 06:46:04,935] 1026 httpx - INFO - HTTP Request: POST https://api.openai.com/v1/chat/completions "HTTP/1.1 200 OK"
[2024-03-12 06:46:27,636] 1026 httpx - INFO - HTTP Request: POST https://api.openai.com/v1/chat/completions "HTTP/1.1 200 OK"
[2024-03-12 06:52:42,445] 1026 httpx - INFO - HTTP Request: POST https://api.openai.com/v1/chat/completions "HTTP/1.1 200 OK"
[2024-03-12 06:52:50,582] 1026 httpx - INFO - HTTP Request: POST https://api.openai.com/v1/chat/completions "HTTP/1.1 200 OK"
[2024-03-12 06:52:54,913] 1026 httpx - INFO - HTTP Request: POST https://api.openai.com/v1/chat/completions "HTTP/1.1 200 OK"
[2024-03-12 17:00:29,690] 1771 asyncio - ERROR - Task exception was never retrieved
future: <Task finished name='Task-28760' coro=<WebSocketProtocol13.write_message.<locals>.wrapper() done, defined at C:\Documents\AI\GenAI\E2E Test Case generator\lcenv\Lib\site-packages\tornado\websocket.py:1086> exception=WebSocketClosedError()>
Traceback (most recent call last):
  File "C:\Documents\AI\GenAI\E2E Test Case generator\lcenv\Lib\site-packages\tornado\websocket.py", line 1088, in wrapper
    await fut
tornado.iostream.StreamClosedError: Stream is closed

During handling of the above exception, another exception occurred:

Traceback (most recent call last):
  File "C:\Documents\AI\GenAI\E2E Test Case generator\lcenv\Lib\site-packages\tornado\websocket.py", line 1090, in wrapper
    raise WebSocketClosedError()
tornado.websocket.WebSocketClosedError
